Workbook

Sheet Golden Dataset
A1: case_id | B1: company | C1: role_title | D1: location | E1: jd_text | F1: field_under_test | G1: expected_value | H1: severity | I1: grading_rationale | J1: input_pattern_status | K1: input_pattern_family | L1: input_pattern | M1: root_cause_status | N1: root_cause | O1: source | P1: why_this_test_exists | Q1: actual_output-baseline_v4_prompt-2026-08-13 | R1: pass_fail_output-baseline_v4_prompt-2026-08-13 | S1: actual_output-reasoningredesign_TBD_TBD | T1: pass_fail_output-reasoningredesign_TBD_TBD
A2: GC-001 | B2: Kira (BJAK) | C2: Technical Product Manager | D2: India | E2: About KIRA Our mission is to make money smart, reliable and within reach for everyone. In 2019, we built the first mobile-first, insurance platform, enabling insurance to be accessible online by millions in the region. Today, it's the leading insurance platform in Southeast Asia. Today, we are expanding ways to help people in Asia and it includes spending, saving, investing, exchanging, travelling, and more. Our objective is to build tools that will help people get more from their money and at ease and self reliance, become an expert. We believe AI will help us achieve this in our generation. We are looking for the most talented and driven people we can find. We are looking for people who work for their passion, not counting hours. Who loves building great next-generation products, not status quo. Who cares about redefining how everyone around us can get the best financial applications, not for an exclusive few. We have teams working around the world, with over 20 nationalities and growing from our offices and remotely. Join us and build a better future. The Role BJAK is building a Neobank Superapp for Southeast Asia. As a Technical Product Manager, you’ll own a product vertical end to end—such as payments and expense management, remittance, insurance, or wealth and trading—from strategy, outcomes, and roadmap through to the technical design and delivery of the systems behind it. This is a product where real money moves, mistakes are immediately visible, and licensing, compliance, and third-party rails are core product constraints—not considerations around the edges. We are AI-native by default, but AI is a means, not the goal. The bar is knowing where a model can genuinely improve an outcome, where deterministic systems must remain in control, and how to build products that are reliable, auditable, and trusted when money is involved. What you'll be doing Own a vertical end-to-end — outcomes and metrics, a backlog prioritised by value / risk / dependency / strategic priority, acceptance criteria crisp enough to build and test against. Shape the technical design with engineering — system boundaries, money-movement correctness (idempotency, ledgering, reconciliation), third-party-rail reliance and rail-down behaviour, failure/retry/refund paths, security, latency, scalability, recovery. Make hard trade-offs across correctness, speed, cost, reliability and UX — and defend them to an engineering, compliance or ops lead who pushes back. Treat regulated constraints as first-class product inputs — licensing scope, CDD/KYC and limits, sanctions/PEP screening, transaction monitoring, data residency and privacy. Know which are hard launch gates and which are forward-readiness. Apply AI where it earns its place — define what it's allowed to decide, where a human stays in the loop, how it's evaluated, and what it does when unsure. Every AI-surfaced number traces back to a real record. Ship against external gates — build feature-complete behind flags; go live per rail as each partner and regulatory gate clears. Work across Engineering, Design, Compliance, Operations, Treasury and Finance/Reconciliation. What you'll need Product leadership — significant experience owning a complex technical product end-to-end; strong judgement and decisiveness under ambiguity; ability to balance ambition against technical, regulatory and operational reality; can hold their own with senior engineers. Technical foundation — solid system design (boundaries, datastores, queues/workflows, APIs, failure modes, consistency under concurrency); comfort reading, reviewing and challenging design docs; can sketch an architecture and a sequence. No production code, but technical enough that engineers don't have to simplify. Domain — experience in a regulated / high-consequence domain (payments, banking, remittance, insurance, …) or demonstrable fast-ramp ability; understands why money movement is different (correctness over convenience, irreversible states, partners you don't control). AI judgement — hands-on with LLM-based products; can frame a feature as eval-able (offline, online, human feedback); realistic on hallucination/drift/data gaps, including data-blocked vs model-blocked and when a model must not be in the loop at all. Nice to have — engineer or highly-technical-PM background · zero-to-one · shipped AI-heavy consumer products · defined eval metrics for ML/LLM systems · AI UX + failure-handling intuition · SEA market experience. Outcomes Clear vertical strategy and legible roadmap Ships fast and clears the gates that actually block launch Money is correct and users are never misled about the state of their funds AI features are valuable, predictable and trusted Trade-offs made deliberately under uncertainty and hold up when challenged Engineering, design, compliance, and operations are aligned with minimal friction Location This role is remote, but candidates must be based in China. We are hiring specifically for this market, so applicants should already be based in China. . Language English is our main working language across global teams. Strong English communication is required. Interview Process Our process is designed to move fast: Online assessment or practical task Role-specific interview CEO / final round For strong candidates, we aim to complete the process and make an offer within 1 week from the start of the interview process. Candidates who complete assessments quickly will be prioritized. | F2: remote_type | G2: remote_global | H2: false-negative | I2: JD states explicitly: "This role is remote, but candidates must be based in China. We are hiring specifically for this market, so applicants should already be based in China." This contradicts LinkedIn's own locations_derived ('India') and matches Apify's own ai_remote_location field ('China'), which agrees with the JD text, not the location metadata. | J2: diagnosed | K2: ip_location_conflict | L2: ip_location_field_contradicts_jd_text | M2: not_yet_diagnosed | O2: real_prod_case (D-121, D-129, D-130) | P2: This is D-121's founding case: LinkedIn's own locations_derived says India, but the JD (deep in the text) restricts the role to China. Pre-v5 rubric, the classifier would have wrongly said remote_india from the location field alone. The v5 rubric rewrite (D-129) fixed this, and D-130 verified the fix against this exact posting. This row exists as a permanent regression guard so a future prompt change can't silently reintroduce the mistake. Tests classifyPrompt (junior-titled role, full classify call).
A3: GC-002 | B3: Danaher | C3: HRSD Functional Product Owner | D3: Kolkata, West Bengal, India | E3: Bring more to life. At Danaher, our work saves lives. And each of us plays a part. Fueled by our culture of continuous improvement, we turn ideas into impact – innovating at the speed of life. Our 60,000+ associates work across the globe at more than 15 unique businesses within life sciences, diagnostics, and biotechnology. Are you ready to accelerate your potential and make a real difference? At Danaher, you can build an incredible career at a leading science and technology company, where we’re committed to hiring and developing from within. You’ll thrive in a culture of belonging where you and your unique viewpoint matter. Learn about the Danaher Business System which makes everything possible. The Senior HR Service Delivery Functional Product Owner is responsible for defining business priorities, shaping solutions, and ensuring HRSD capabilities delivered through ServiceNow drive measurable improvements in service efficiency, employee experience, and adoption. This role serves as the primary functional owner of HRSD platform demand, partnering closely with HRSD Operations, Centers of Excellence, and the HRIT HRSD Technical Product Owner to deliver scalable, high-impact solutions aligned to enterprise service delivery standards. In This Role, You Will Have The Opportunity To Define and prioritize HRSD demand, translating business needs and operational insights into a clear, value-driven functional backlog. Own the creation and refinement of epics, features, and user stories aligned to HR outcomes, including success measures and acceptance criteria. Make trade-off decisions across scope, speed, and experience to maximize the value delivered through HRSD capabilities. Partner closely with the HRIT HRSD Technical Product Owner to ensure backlog readiness, feasibility, and alignment with ServiceNow platform capabilities. Validate delivered solutions against business requirements, ensuring improvements in self-service adoption, Tier 1 effectiveness, and overall service performance. The Essential Requirements Of The Job Include Bachelor’s degree in HR, Business, Information Systems, or a related field. Minimum of 7 years of hands‑on experience leading ServiceNow HRSD as Product Owner, Business Analyst, or Functional HRSD Architect. Hands-on experience working with ServiceNow HRSD (case management, knowledge, employee service center) in a product owner, BA, or functional lead capacity. Proven ability to translate business needs into structured requirements, prioritize work based on value, and operate in a backlog-driven delivery model. It would be a plus if you also possess previous experience in: Leading or supporting enterprise ServiceNow HRSD implementations or enhancements. Agile or product management practices, including backlog management and release cycles. Driving HRSD service model improvements (e.g., Tier 0/1 optimization, automation, AI-enabled service delivery). Danaher offers a broad array of comprehensive, competitive benefit programs that add value to our lives. Whether it’s a health care program or paid time off, our programs contribute to life beyond the job. Check out our benefits at Danaher Benefits Info. Join our winning team today. Together, we’ll accelerate the real-life impact of tomorrow’s science and technology. We partner with customers across the globe to help them solve their most complex challenges, architecting solutions that bring the power of science to life. For more information, visit www.danaher.com. | F3: remote_type | G3: remote_india | H3: false-negative | I3: No explicit "remote" sentence appears in the JD body text itself — the remote evidence is structural: LinkedIn's own schema.org location_type field is TELECOMMUTE, and Apify's own ai_work_arrangement field says "Remote OK". remote_check returned not_remote ('other' at the time) anyway, missing both structured signals. Note: this differs slightly from how the case was described when first logged (D-149 said "explicit remote language in the JD") — checking the raw JD text directly found the explicit signal lives in structured metadata, not prose. | J3: not_applicable | M3: diagnosed | N3: reasoning_after_verdict | O3: real_prod_case (D-146/D-147, cited in D-149) | P3: One of the 2 confirmed real remote_check misses (Session 30, 2026-08-10 audit) that directly motivated D-149's reason-before-classify redesign. Exists to verify D-149 actually fixes what it was built to fix, once implemented. Tests remoteCheckPrompt (senior-titled role, D-133/D-136 skip classify entirely), not classifyPrompt — the two prompts share this rubric verbatim, so this row also guards remoteCheckPrompt specifically.
A4: GC-003 | B4: Equinix | C4: Product Manager - Senior Staff - Data & AI | D4: Bengaluru, Karnataka, India | E4: Who are we? Equinix is the world’s digital infrastructure company®, shortening the path to connectivity to enable the innovations that enrich our work, life and planet. A place where bold ideas are welcomed, human connection is valued, and everyone has the opportunity to shape their future. A career at Equinix means being at the center of shaping what comes next and amplifying customer value through innovation and impact. You’ll work across teams, influence key decisions, and help shape the path forward. You’ll find belonging, purpose, and a team that welcomes you—because when you feel valued, you’re empowered to do your best work. Job Description About the Role We're looking for a Senior/Staff Product Manager to join our Data & Analytics team and own the product strategy for data platforms, analytics tooling, and AI-driven capabilities. This role sits at the intersection of data engineering, business strategy, and applied AI — you'll translate complex business needs into a clear product roadmap, while working hand-in-hand with data engineers to ship scalable, reliable, and high-impact solutions. This is a high-visibility, cross-functional role for someone who can operate at both strategic and technical depth, partner effectively with engineering and business stakeholders, and has hands-on experience shipping AI/ML-powered products. What You'll Do Product Management for Data, BI and AI product Manage and execute the data analytics product vision to help business teams adopt data and use it confidently for decision-making. Lead end-to-end delivery of AI-powered analytics products — from problem framing and data feasibility assessment through model evaluation, deployment, and adoption. Define success metrics, build business cases, and prioritize a roadmap balancing technical debt, platform scalability, and business impact. Provide statistical techniques, quantitative data analysis, predictive analytics, and scenario-based analysis to support product decisions. Cross-Functional Partnership Engage with cross-functional business and IT teams to understand requirements, analyze, design, and help build solutions for analytics and data science products. Partner closely with Data Engineering to design scalable data pipelines, infrastructure, and platform capabilities that support analytics and AI use cases. Work directly with business partners (Sales, Marketing, Customer Success...) to identify high-value problems, gather requirements, and translate them into actionable product specs. Collaborate closely with analysts and data scientists across the organization, including on model development, evaluation, and responsible AI practices (bias, explainability, governance). Analyze complex requirements and translate them into simple, actionable user stories. Maintain deep knowledge of cross-functional data and ensure data quality on all products launched. Delivery & Execution Build dashboard prototypes to help business stakeholders visualize end products. Get involved in testing analytic products for functionality, user interface, and data quality. Provide technical support to business teams for self-serve analytics; define best practices and develop user guides. Follow agile methodologies and deliver continuous enhancements to products. Optimize release management to strike the right balance between business goals and delivery capacity. Identify and manage risks in release delivery and communicate clearly with stakeholders, including mitigation plans. Debug and identify root causes for critical issues and provide solution recommendations. Ensure data security and compliance measures are in place for every product delivered. Leadership & Documentation Support senior management by creating architecture, project management, and roadmap documentation. Own the product lifecycle: discovery, prioritization, requirements, launch, and post-launch iteration. Evangelize data-driven and AI-driven decision-making across the organization. Mentor junior PMs and contribute to product process and best practices (especially at the Staff level). Maintain a strong personal base of knowledge on data platform technology, industry practices, trends, and emerging issues. What You'll Need Education Master's Degree in Statistics, Analytics, Mathematics, Economics, or a related quantitative field (preferred). Experience 8+ years of product management experience (3+ years as a Data Analyst/similar role supporting cross-functional global business units, for candidates coming from an analytics background), with at least 2–3 years focused on data platforms, analytics, or AI/ML products. Demonstrated experience shipping AI/ML-powered features or products (e.g., recommendation systems, predictive models, LLM-based applications, automation tools) — this is required. Proven track record partnering closely with data engineering teams on data infrastructure, pipelines, or platform-level products. Experience working directly with business stakeholders to translate ambiguous needs into structured product requirements. Experience building customer-centric data products, sales-centric analytic products, and executive metrics/reporting. Experience with data from the Customer Experience and Sales domains. Experience in the data center domain and knowledge of data center products are nice-to-have. Skills Strong technical fluency: comfortable discussing data architecture, ETL/ELT pipelines, data modeling, and ML/AI concepts with engineering teams. Strong statistical and data analysis skills, including regressions, classification, anomaly detection, and hypothesis testing, with experience applying these techniques in real analyses. Excellent communication and stakeholder management skills; able to flex between technical depth and business-level storytelling. Strong analytical skills in breaking down complex problems, processes, and systems to propose solutions. Ability to document and prototype business use cases and data flows. Strong quantitative skills; comfortable with SQL and interpreting data to drive decisions. Experience with agile product development practices, roadmap planning, and prioritization frameworks. Familiarity with the AI/ML lifecycle (data prep, model training/evaluation, deployment, monitoring) and responsible AI considerations. Proven experience building dashboards in Tableau, Power BI, QlikView, or similar tools. Ability to understand complex data models and connect to varied data sources such as SFDC, Exasol, Google BigQuery, and AWS. Tableau certification is desirable, along with experience on Tableau Online (cloud), Tableau Server, and Tableau Prep. Nice to Have Prior experience as a data analyst, data engineer, or data scientist before transitioning into product. Experience with generative AI / LLM-based product development. Note - This is a business facing role we need this positionsupporting position to be remote and provide support during US hours (4:00 PM IST to 12:00 AM IST) Equinix is committed to ensuring that our employment process is open to all individuals, including those with a disability. If you are a qualified candidate and need assistance or an accommodation, please let us know by completing this form. Equinix is an Equal Employment Opportunity and, in the U.S., an Affirmative Action employer. All qualified applicants will receive consideration for employment without regard to unlawful consideration of race, color, religion, creed, national or ethnic origin, ancestry, place of birth, citizenship, sex, pregnancy / childbirth or related medical conditions, sexual orientation, gender identity or expression, marital or domestic partnership status, age, veteran or military status, physical or mental disability, medical condition, genetic information, political / organizational affiliation, status as a victim or family member of a victim of crime or abuse, or any other status protected by applicable law. We use artificial intelligence in our hiring process. Learn more here. | F4: remote_type | G4: remote_india | H4: false-negative | I4: JD explicitly states: "This is a business facing role we need this position supporting position to be remote and provide support during US hours (4:00 PM IST to 12:00 AM IST)." (Awkward phrasing in the original — likely an editing artifact — but the remote confirmation is unambiguous.) remote_check returned not_remote ('other' at the time) despite this explicit line. | J4: diagnosed | K4: ip_signal_unclear | L4: ip_remote_stated_but_badly_worded | M4: diagnosed | N4: reasoning_after_verdict | O4: real_prod_case (D-146/D-147, cited in D-149) | P4: The second of the 2 confirmed real remote_check misses (Session 30, 2026-08-10 audit) behind D-149. Same purpose as GC-002: verify D-149's reasoning-before-verdict reorder actually changes the verdict, not just adds reasoning text around the same wrong answer. Tests remoteCheckPrompt (senior-titled role).
A5: GC-004 | B5: Interview Kickstart | C5: Associate Product Manager | D5: Bengaluru, Karnataka, India | E5: Let's start with who we are: Interviews can be hard. And when it comes to the top tech companies like Google, Facebook, Netflix, etc., they can be downright brutal. Most candidates don’t make it simply because they don’t prepare well enough. IK helps candidates nail the toughest tech interviews. At IK, current and former hiring managers at these top companies take candidates through an intense prep course to prepare them to crack the toughest Technical interviews. You could think of us as ‘the everything store’ for career transitions and interview skill development. How do we do that, you ask? We have a structured way of helping folks crack interviews- Career accelerator course End-to-end courses + platform More than 750+ instructors from Google, FB, Amazon, Netflix, Dropbox, and other top Silicon Valley companies. And, to date, we have trained over 27000+ engineers! What’s more exciting is that we are completely remote and hiring the best people we can find regardless of geo. Sounds interesting? Then here’s some more information about the role Position Overview We’re looking for an Associate Product Manager (APM) to join our Product Management team at IK. In this role, you’ll support the discovery, development, and improvement of products that help users succeed in their career journeys. You’ll work closely with engineering, design, and other cross-functional teams to define problems, shape solutions, and deliver meaningful user experiences. This role is ideal for someone early in their product career who is curious, structured in their thinking, and excited to learn how great products are built Responsibilities: Support the end-to-end product lifecycle—from problem discovery to delivery and iteration Work with engineers and designers to define requirements, clarify scope, and prioritize work Gather and synthesize user feedback, product data, and internal inputs to inform decisions Help define product goals, success metrics, and release plans Assist with competitive research and market understanding to improve product direction Participate in agile ceremonies such as sprint planning, stand-ups, and retrospectives Advocate for user needs while balancing business and technical constraints What would Excite us : Bachelor’s or Master’s degree in Business, Marketing, Computer Science, or a related field. 1-3 years of experience in product management, business analysis, or a growth-focused role in a tech environment. Hands-on AI experience is mandatory. Candidates should have built AI-powered applications or workflows using tools like Claude, Supabase, Vercel, Lovable (or similar), be data-driven, and be able to demonstrate their contributions; experience with AI Voice Bots or AI Support Agents is a strong plus. Strong analytical and problem-solving skills with a data-driven approach. Excellent communication and collaboration skills for effective cross-functional teamwork. A deep interest in technology, product development, and market trends. Agile and adaptable, with the ability to thrive in a fast-paced and evolving tech landscape. What would excite you? Join a forward-thinking company where innovation and growth are paramount. Collaborate with a world-class team on impactful projects. Play a key role in the direction and success of diverse tech products. Enjoy a competitive compensation package in a supportive and dynamic work environment Complete ownership; there is minimal management and extreme autonomy | F5: remote_type | G5: remote_india | H5: false-negative | I5: JD: "we are completely remote and hiring the best people we can find regardless of geo" — no region restriction, open to India. | J5: not_applicable | M5: not_applicable | O5: real_prod_case | P5: Happy-path baseline for remote_type: clean, unambiguous remote-anywhere posting. Regression guard so a future prompt change can't silently start misreading the easy 90% case. Tests classifyPrompt (junior-titled role). Human-verified by Sakshi against the pulled DB row before use — see Session 36.
A6: GC-005 | B6: Interview Kickstart | C6: Associate Product Manager | D6: Bengaluru, Karnataka, India | E6: Let's start with who we are: Interviews can be hard. And when it comes to the top tech companies like Google, Facebook, Netflix, etc., they can be downright brutal. Most candidates don’t make it simply because they don’t prepare well enough. IK helps candidates nail the toughest tech interviews. At IK, current and former hiring managers at these top companies take candidates through an intense prep course to prepare them to crack the toughest Technical interviews. You could think of us as ‘the everything store’ for career transitions and interview skill development. How do we do that, you ask? We have a structured way of helping folks crack interviews- Career accelerator course End-to-end courses + platform More than 750+ instructors from Google, FB, Amazon, Netflix, Dropbox, and other top Silicon Valley companies. And, to date, we have trained over 27000+ engineers! What’s more exciting is that we are completely remote and hiring the best people we can find regardless of geo. Sounds interesting? Then here’s some more information about the role Position Overview We’re looking for an Associate Product Manager (APM) to join our Product Management team at IK. In this role, you’ll support the discovery, development, and improvement of products that help users succeed in their career journeys. You’ll work closely with engineering, design, and other cross-functional teams to define problems, shape solutions, and deliver meaningful user experiences. This role is ideal for someone early in their product career who is curious, structured in their thinking, and excited to learn how great products are built Responsibilities: Support the end-to-end product lifecycle—from problem discovery to delivery and iteration Work with engineers and designers to define requirements, clarify scope, and prioritize work Gather and synthesize user feedback, product data, and internal inputs to inform decisions Help define product goals, success metrics, and release plans Assist with competitive research and market understanding to improve product direction Participate in agile ceremonies such as sprint planning, stand-ups, and retrospectives Advocate for user needs while balancing business and technical constraints What would Excite us : Bachelor’s or Master’s degree in Business, Marketing, Computer Science, or a related field. 1-3 years of experience in product management, business analysis, or a growth-focused role in a tech environment. Hands-on AI experience is mandatory. Candidates should have built AI-powered applications or workflows using tools like Claude, Supabase, Vercel, Lovable (or similar), be data-driven, and be able to demonstrate their contributions; experience with AI Voice Bots or AI Support Agents is a strong plus. Strong analytical and problem-solving skills with a data-driven approach. Excellent communication and collaboration skills for effective cross-functional teamwork. A deep interest in technology, product development, and market trends. Agile and adaptable, with the ability to thrive in a fast-paced and evolving tech landscape. What would excite you? Join a forward-thinking company where innovation and growth are paramount. Collaborate with a world-class team on impactful projects. Play a key role in the direction and success of diverse tech products. Enjoy a competitive compensation package in a supportive and dynamic work environment Complete ownership; there is minimal management and extreme autonomy | F6: geo_explicit | G6: =TRUE() -> TRUE | H6: false-positive | I6: JD explicitly addresses eligibility rather than staying silent: "hiring the best people we can find regardless of geo" is an affirmative worldwide statement, not an absence of one. | J6: not_applicable | M6: not_applicable | O6: real_prod_case | P6: Happy-path baseline for geo_explicit=true (explicit-eligibility case, contrasts with GC-007's geo_explicit=false silent case). Tests classifyPrompt.
A7: GC-006 | B7: Interview Kickstart | C7: Associate Product Manager | D7: Bengaluru, Karnataka, India | E7: Let's start with who we are: Interviews can be hard. And when it comes to the top tech companies like Google, Facebook, Netflix, etc., they can be downright brutal. Most candidates don’t make it simply because they don’t prepare well enough. IK helps candidates nail the toughest tech interviews. At IK, current and former hiring managers at these top companies take candidates through an intense prep course to prepare them to crack the toughest Technical interviews. You could think of us as ‘the everything store’ for career transitions and interview skill development. How do we do that, you ask? We have a structured way of helping folks crack interviews- Career accelerator course End-to-end courses + platform More than 750+ instructors from Google, FB, Amazon, Netflix, Dropbox, and other top Silicon Valley companies. And, to date, we have trained over 27000+ engineers! What’s more exciting is that we are completely remote and hiring the best people we can find regardless of geo. Sounds interesting? Then here’s some more information about the role Position Overview We’re looking for an Associate Product Manager (APM) to join our Product Management team at IK. In this role, you’ll support the discovery, development, and improvement of products that help users succeed in their career journeys. You’ll work closely with engineering, design, and other cross-functional teams to define problems, shape solutions, and deliver meaningful user experiences. This role is ideal for someone early in their product career who is curious, structured in their thinking, and excited to learn how great products are built Responsibilities: Support the end-to-end product lifecycle—from problem discovery to delivery and iteration Work with engineers and designers to define requirements, clarify scope, and prioritize work Gather and synthesize user feedback, product data, and internal inputs to inform decisions Help define product goals, success metrics, and release plans Assist with competitive research and market understanding to improve product direction Participate in agile ceremonies such as sprint planning, stand-ups, and retrospectives Advocate for user needs while balancing business and technical constraints What would Excite us : Bachelor’s or Master’s degree in Business, Marketing, Computer Science, or a related field. 1-3 years of experience in product management, business analysis, or a growth-focused role in a tech environment. Hands-on AI experience is mandatory. Candidates should have built AI-powered applications or workflows using tools like Claude, Supabase, Vercel, Lovable (or similar), be data-driven, and be able to demonstrate their contributions; experience with AI Voice Bots or AI Support Agents is a strong plus. Strong analytical and problem-solving skills with a data-driven approach. Excellent communication and collaboration skills for effective cross-functional teamwork. A deep interest in technology, product development, and market trends. Agile and adaptable, with the ability to thrive in a fast-paced and evolving tech landscape. What would excite you? Join a forward-thinking company where innovation and growth are paramount. Collaborate with a world-class team on impactful projects. Play a key role in the direction and success of diverse tech products. Enjoy a competitive compensation package in a supportive and dynamic work environment Complete ownership; there is minimal management and extreme autonomy | F7: is_ai | G7: ai | H7: false-negative | I7: JD: "Hands-on AI experience is mandatory... built AI-powered applications or workflows using tools like Claude, Supabase, Vercel, Lovable." NOTE: the product itself (interview-prep courses) is not AI-centered — only the role's required skillset is. Borderline call, flagged for Sakshi's explicit confirmation before treating as settled ground truth (D-50: human verdict is authoritative, not the model's). | J7: not_applicable | M7: not_applicable | O7: real_prod_case | P7: FLAGGED, NOT YET CONFIRMED: is_ai here hinges on whether 'role requires AI-building skills' counts as 'product or role centers on AI/ML/LLMs' per the rubric's own wording — the product itself doesn't. Needs Sakshi's explicit sign-off before this row is trusted as a happy-path baseline rather than reclassified as a diagnosed edge case.
A8: GC-007 | B8: Interview Kickstart | C8: Associate Product Manager | D8: Bengaluru, Karnataka, India | E8: Let's start with who we are: Interviews can be hard. And when it comes to the top tech companies like Google, Facebook, Netflix, etc., they can be downright brutal. Most candidates don’t make it simply because they don’t prepare well enough. IK helps candidates nail the toughest tech interviews. At IK, current and former hiring managers at these top companies take candidates through an intense prep course to prepare them to crack the toughest Technical interviews. You could think of us as ‘the everything store’ for career transitions and interview skill development. How do we do that, you ask? We have a structured way of helping folks crack interviews- Career accelerator course End-to-end courses + platform More than 750+ instructors from Google, FB, Amazon, Netflix, Dropbox, and other top Silicon Valley companies. And, to date, we have trained over 27000+ engineers! What’s more exciting is that we are completely remote and hiring the best people we can find regardless of geo. Sounds interesting? Then here’s some more information about the role Position Overview We’re looking for an Associate Product Manager (APM) to join our Product Management team at IK. In this role, you’ll support the discovery, development, and improvement of products that help users succeed in their career journeys. You’ll work closely with engineering, design, and other cross-functional teams to define problems, shape solutions, and deliver meaningful user experiences. This role is ideal for someone early in their product career who is curious, structured in their thinking, and excited to learn how great products are built Responsibilities: Support the end-to-end product lifecycle—from problem discovery to delivery and iteration Work with engineers and designers to define requirements, clarify scope, and prioritize work Gather and synthesize user feedback, product data, and internal inputs to inform decisions Help define product goals, success metrics, and release plans Assist with competitive research and market understanding to improve product direction Participate in agile ceremonies such as sprint planning, stand-ups, and retrospectives Advocate for user needs while balancing business and technical constraints What would Excite us : Bachelor’s or Master’s degree in Business, Marketing, Computer Science, or a related field. 1-3 years of experience in product management, business analysis, or a growth-focused role in a tech environment. Hands-on AI experience is mandatory. Candidates should have built AI-powered applications or workflows using tools like Claude, Supabase, Vercel, Lovable (or similar), be data-driven, and be able to demonstrate their contributions; experience with AI Voice Bots or AI Support Agents is a strong plus. Strong analytical and problem-solving skills with a data-driven approach. Excellent communication and collaboration skills for effective cross-functional teamwork. A deep interest in technology, product development, and market trends. Agile and adaptable, with the ability to thrive in a fast-paced and evolving tech landscape. What would excite you? Join a forward-thinking company where innovation and growth are paramount. Collaborate with a world-class team on impactful projects. Play a key role in the direction and success of diverse tech products. Enjoy a competitive compensation package in a supportive and dynamic work environment Complete ownership; there is minimal management and extreme autonomy | F8: technical_depth | G8: 4 | H8: false-positive | I8: JD requires hands-on building of "AI-powered applications or workflows" with specific tools (Claude, Supabase, Vercel, Lovable) — closer to rubric's depth-5 ("writes queries/code, deep ML/infra fluency") than a typical APM, but not full engineering ownership. Judgment call within a plausible range (3-5); not a single unambiguous integer. | J8: not_applicable | M8: not_applicable | O8: real_prod_case | P8: Happy-path candidate for technical_depth, but the exact integer is a judgment call, not a citable fact — treat expected_value as approximate (3-5 all defensible) rather than an exact-match target unless Sakshi commits to one number.
A9: GC-008 | B9: Cloud Security Web | C9: Associate Product Manager - Product Operations & Adoption | D9: India | E9: EchoPad.ai is building AI-powered healthcare products that automate clinical documentation, patient communication, and operational workflows. Location: Remote (India) Role: Associate Product Manager - Product Operations & Adoption We are looking for someone very strong in: Customer onboarding and pilot management Product usage analysis and reporting QA, feedback collection, and issue prioritization Coordinating across customers, product, and engineering Driving product adoption and customer success We are looking for strong executors who can demonstrate relevant projects, campaigns, or measurable results. Candidates must be able to contribute from day one and work with high ownership. Preferred: SQL, SaaS onboarding, dashboard creation, and healthcare operations. Company: https://echopad.ai | F9: remote_type | G9: remote_india | H9: false-negative | I9: JD: "Location: Remote (India)" — explicit and unambiguous. | J9: not_applicable | M9: not_applicable | O9: real_prod_case | P9: Happy-path baseline for remote_type, contrast case to GC-004: same India-remote pool, different company/domain (healthcare SaaS). Tests classifyPrompt.
A10: GC-009 | B10: Cloud Security Web | C10: Associate Product Manager - Product Operations & Adoption | D10: India | E10: EchoPad.ai is building AI-powered healthcare products that automate clinical documentation, patient communication, and operational workflows. Location: Remote (India) Role: Associate Product Manager - Product Operations & Adoption We are looking for someone very strong in: Customer onboarding and pilot management Product usage analysis and reporting QA, feedback collection, and issue prioritization Coordinating across customers, product, and engineering Driving product adoption and customer success We are looking for strong executors who can demonstrate relevant projects, campaigns, or measurable results. Candidates must be able to contribute from day one and work with high ownership. Preferred: SQL, SaaS onboarding, dashboard creation, and healthcare operations. Company: https://echopad.ai | F10: geo_explicit | G10: =TRUE() -> TRUE | H10: false-positive | I10: JD: "Location: Remote (India)" names the region directly. | J10: not_applicable | M10: not_applicable | O10: real_prod_case | P10: Happy-path baseline for geo_explicit=true, cleanest possible case (region named directly in a labeled Location field, no inference needed).
A11: GC-010 | B11: Cloud Security Web | C11: Associate Product Manager - Product Operations & Adoption | D11: India | E11: EchoPad.ai is building AI-powered healthcare products that automate clinical documentation, patient communication, and operational workflows. Location: Remote (India) Role: Associate Product Manager - Product Operations & Adoption We are looking for someone very strong in: Customer onboarding and pilot management Product usage analysis and reporting QA, feedback collection, and issue prioritization Coordinating across customers, product, and engineering Driving product adoption and customer success We are looking for strong executors who can demonstrate relevant projects, campaigns, or measurable results. Candidates must be able to contribute from day one and work with high ownership. Preferred: SQL, SaaS onboarding, dashboard creation, and healthcare operations. Company: https://echopad.ai | F11: is_ai | G11: ai | H11: false-negative | I11: JD: "EchoPad.ai is building AI-powered healthcare products that automate clinical documentation..." — the product itself is explicitly AI-centered, not just the role's required skills. | J11: not_applicable | M11: not_applicable | O11: real_prod_case | P11: Happy-path baseline for is_ai=ai, and the cleaner contrast to GC-006's borderline case: here the PRODUCT is AI-centered by the JD's own words, not just the role's skill requirements.
A12: GC-011 | B12: Cloud Security Web | C12: Associate Product Manager - Product Operations & Adoption | D12: India | E12: EchoPad.ai is building AI-powered healthcare products that automate clinical documentation, patient communication, and operational workflows. Location: Remote (India) Role: Associate Product Manager - Product Operations & Adoption We are looking for someone very strong in: Customer onboarding and pilot management Product usage analysis and reporting QA, feedback collection, and issue prioritization Coordinating across customers, product, and engineering Driving product adoption and customer success We are looking for strong executors who can demonstrate relevant projects, campaigns, or measurable results. Candidates must be able to contribute from day one and work with high ownership. Preferred: SQL, SaaS onboarding, dashboard creation, and healthcare operations. Company: https://echopad.ai | F12: is_technical | G12: non_technical | H12: false-positive | I12: JD lists onboarding, usage analysis/reporting, QA/feedback triage, and cross-team coordination as the core duties; SQL and dashboarding appear only under "Preferred," not required. | J12: not_applicable | M12: not_applicable | O12: real_prod_case | P12: Happy-path baseline for is_technical=non_technical, contrast to GC-006/007's technical IK posting.
A13: GC-012 | B13: Cloud Security Web | C13: Associate Product Manager - Product Operations & Adoption | D13: India | E13: EchoPad.ai is building AI-powered healthcare products that automate clinical documentation, patient communication, and operational workflows. Location: Remote (India) Role: Associate Product Manager - Product Operations & Adoption We are looking for someone very strong in: Customer onboarding and pilot management Product usage analysis and reporting QA, feedback collection, and issue prioritization Coordinating across customers, product, and engineering Driving product adoption and customer success We are looking for strong executors who can demonstrate relevant projects, campaigns, or measurable results. Candidates must be able to contribute from day one and work with high ownership. Preferred: SQL, SaaS onboarding, dashboard creation, and healthcare operations. Company: https://echopad.ai | F13: technical_depth | G13: 2 | H13: false-negative | I13: JD lists SQL/dashboard creation only under "Preferred," not required — the rubric's own depth-3 example is "reads dashboards, writes basic SQL," which is closer to what's described here than depth-2's "pure stakeholder/ops PM." FLAGGED: this row's expected_value (2) may actually undershoot the rubric's own depth-3 anchor — needs Sakshi's read before treating as settled. | J13: not_applicable | M13: not_applicable | O13: real_prod_case | P13: FLAGGED, NOT YET CONFIRMED: technical_depth=2 vs. the rubric's own depth-3 example text look like they may be in tension for this exact JD (preferred-not-required SQL/dashboards). Resolve before trusting this row's expected_value as ground truth.
A14: GC-013 | B14: Ethos | C14: Expert Opportunity - Associate Product Manager | D14: India | E14: About This Opportunity We're working with a leading foundational AI lab to find experienced associate product managers at top technology companies who can help train their latest language model on professional presentation and slide deck tasks. We're looking for APMs with 4+ years shipping products and presenting strategy, roadmaps, and reviews to create, evaluate, and refine AI-generated presentations and slide decks across core workflows: product strategy decks, roadmap presentations, product review documents, launch readiness decks, executive check-ins, and OKR review materials. Compensation: $80/hour Commitment: Flexible, 5-20 hours per week (or more if desired) Location: Fully remote, work on your own schedule Start date: ASAP Qualifications 4+ years as a product manager at a top technology company Track record of presenting product strategy to executives and cross-functional teams Expert-level PowerPoint and slide craftsmanship, with excellent written communication and attention to detail About Ethos Ethos is a new expert network built by a McKinsey/SoftBank/DeepMind team and backed by world-leading investors like General Catalyst. We connect experts with investors and consultancies for paid expert calls, speaking engagements, and advisory opportunities. Key Requirements 4+ years as a product manager at a top technology company Track record of presenting product strategy to executives and cross-functional teams Expert-level PowerPoint and slide craftsmanship, with excellent written communication and attention to detail | F14: remote_type | G14: remote_india | H14: false-negative | I14: No explicit region named anywhere in the JD ("Fully remote, work on your own schedule" states no geographic restriction) — this is the fail-open default path (remote_india + geo_explicit=false) confirmed correct, not an explicit-eligibility case. | J14: not_applicable | M14: not_applicable | O14: real_prod_case | P14: Confirms the fail-open default (classify.ts / D-75's geoRecheckPrompt trigger condition) lands correctly on a genuinely silent-on-geography posting — this is the specific mechanism GC-005/GC-009 don't test, since both of those have explicit region statements.
A15: GC-014 | B15: Ethos | C15: Expert Opportunity - Associate Product Manager | D15: India | E15: About This Opportunity We're working with a leading foundational AI lab to find experienced associate product managers at top technology companies who can help train their latest language model on professional presentation and slide deck tasks. We're looking for APMs with 4+ years shipping products and presenting strategy, roadmaps, and reviews to create, evaluate, and refine AI-generated presentations and slide decks across core workflows: product strategy decks, roadmap presentations, product review documents, launch readiness decks, executive check-ins, and OKR review materials. Compensation: $80/hour Commitment: Flexible, 5-20 hours per week (or more if desired) Location: Fully remote, work on your own schedule Start date: ASAP Qualifications 4+ years as a product manager at a top technology company Track record of presenting product strategy to executives and cross-functional teams Expert-level PowerPoint and slide craftsmanship, with excellent written communication and attention to detail About Ethos Ethos is a new expert network built by a McKinsey/SoftBank/DeepMind team and backed by world-leading investors like General Catalyst. We connect experts with investors and consultancies for paid expert calls, speaking engagements, and advisory opportunities. Key Requirements 4+ years as a product manager at a top technology company Track record of presenting product strategy to executives and cross-functional teams Expert-level PowerPoint and slide craftsmanship, with excellent written communication and attention to detail | F15: geo_explicit | G15: =FALSE() -> FALSE | H15: false-positive | I15: JD never names India, Asia, or "worldwide" — "Fully remote, work on your own schedule" states no restriction but also names no eligible region, which the rubric treats as silence, not an explicit statement. | J15: not_applicable | M15: not_applicable | O15: real_prod_case | P15: Companion row to GC-013 — confirms geo_explicit correctly reads FALSE here (silence) rather than TRUE, which is what would incorrectly skip the fail-open safety net (geoRecheckPrompt, D-75).
A16: GC-015 | B16: Ethos | C16: Expert Opportunity - Associate Product Manager | D16: India | E16: About This Opportunity We're working with a leading foundational AI lab to find experienced associate product managers at top technology companies who can help train their latest language model on professional presentation and slide deck tasks. We're looking for APMs with 4+ years shipping products and presenting strategy, roadmaps, and reviews to create, evaluate, and refine AI-generated presentations and slide decks across core workflows: product strategy decks, roadmap presentations, product review documents, launch readiness decks, executive check-ins, and OKR review materials. Compensation: $80/hour Commitment: Flexible, 5-20 hours per week (or more if desired) Location: Fully remote, work on your own schedule Start date: ASAP Qualifications 4+ years as a product manager at a top technology company Track record of presenting product strategy to executives and cross-functional teams Expert-level PowerPoint and slide craftsmanship, with excellent written communication and attention to detail About Ethos Ethos is a new expert network built by a McKinsey/SoftBank/DeepMind team and backed by world-leading investors like General Catalyst. We connect experts with investors and consultancies for paid expert calls, speaking engagements, and advisory opportunities. Key Requirements 4+ years as a product manager at a top technology company Track record of presenting product strategy to executives and cross-functional teams Expert-level PowerPoint and slide craftsmanship, with excellent written communication and attention to detail | F16: is_ai | G16: ai | H16: false-negative | I16: JD: "We're working with a leading foundational AI lab... help train their latest language model" — the role itself is AI-lab-facing work (RLHF-style evaluation of AI-generated output), unambiguous. | J16: not_applicable | M16: not_applicable | O16: real_prod_case | P16: Happy-path baseline for is_ai=ai — third distinct flavor of AI-relatedness after GC-006 (role needs AI skills, borderline) and GC-010 (product is AI, clean): here the WORK is literally training an AI lab's model, a third clean case.

Sheet Legend
A1: Section | B1: Column | C1: Notes (technical) | D1: In Plain Language
A2: Identity | B2: case_id | C2: Short stable ID, format GC-###. | D2: A name tag for the row (GC-001, GC-002...) so you can refer to a specific test case.
A3: Identity | B3: company | C3: For quick human lookup only — not used by the prompt. | D3: Just there so a human recognizes the row at a glance. The AI never sees this.
A4: Input | B4: role_title | C4: Exactly what gets passed into classifyPrompt / remoteCheckPrompt. | D4: The job title, same as what the real posting shows.
A5: Input | B5: location | C5: Exactly what gets passed into classifyPrompt / remoteCheckPrompt. | D5: The posting's own location field, same as what the real posting shows.
A6: Input | B6: jd_text | C6: Exactly what gets passed into classifyPrompt / remoteCheckPrompt. Usually the longest cell in the row. | D6: The full job description text — same as what the real posting shows.
A7: Test target | B7: field_under_test | C7: Which of classifyPrompt's output keys this row is checking (e.g. remote_type, salary_status). One row tests ONE field. | D7: What question this specific row is checking — not the whole AI output, just one part of it.
A8: Test target | B8: expected_value | C8: The correct answer, verified by a human. | D8: What the AI SHOULD say for field_under_test, according to a human who checked.
A9: Grading | B9: grading_rationale | C9: Quote or close paraphrase of the JD line that proves expected_value. Keep it short and citeable. | D9: The proof — a short quote from the posting showing why the expected answer is correct.
A10: Tags — input pattern | B10: input_pattern_status | C10: 'diagnosed' (a pattern was found and named), 'not_applicable' (checked — nothing tricky in the input), or 'not_yet_diagnosed' (this angle hasn't been checked for this case). Never blank. | D10: Was anything actually tricky in the job posting? diagnosed = yes, found it. not_applicable = checked, nothing tricky. not_yet_diagnosed = nobody's looked yet.
A11: Tags — input pattern | B11: input_pattern_family | C11: The short, structured umbrella category the specific input_pattern belongs to (e.g. ip_location_conflict). Same diagnosed-status gating as input_pattern — filled in only when input_pattern_status = 'diagnosed'. Exists so you can roll up / filter / chart by family without reading every specific slug. See the "Failure Categories" sheet for definitions. (D-155) | D11: The BROAD family this tricky-posting case belongs to (e.g. 'a location conflict of some kind') — short and consistent across cases, so you can group similar failures without reading the full specific description each time.
A12: Tags — input pattern | B12: input_pattern | C12: The specific slug naming the exact pattern — filled in ONLY when input_pattern_status = 'diagnosed'. Prefixed ip_ (e.g. ip_location_field_contradicts_jd_text) so the value is self-identifying even quoted out of context. Paired with input_pattern_family (the broader umbrella this specific case belongs to). See the "Failure Categories" sheet for definitions. (D-155) | D12: WHAT was tricky about the posting, if anything, spelled out in full (e.g. 'the location field contradicts the JD text'). Only filled in when the status column says 'diagnosed'.
... A18: Results | B18: actual_output-{date} / pass_fail_output-{date} | C18: One pair of columns per prompt version actually tested — filled in per run, NOT authored up front. Column names follow <slug>_<CLASSIFIER_VERSION>_<PROMPT_VERSION>, pasted verbatim from the live constants in lib/ai/prompts.ts at the moment that version is actually run — never a hand-typed calendar date (D-154). | D18: The scoreboard. Each time a prompt version runs against this row, a new pair of columns records what it actually answered and whether that matched expected_value. The column's own name tells you exactly which code version produced that answer.
A20: Failure-category definitions (Title/Definition/Example for every input_pattern and root_cause value) live on the "Failure Categories" sheet, not here.

Sheet Failure Categories
A1: Column | B1: Value | C1: Title | D1: Definition (does a NEW case belong here?) | E1: Example
A2: SECTION 1 — Status values (shared vocabulary for BOTH input_pattern_status and root_cause_status)
A3: input_pattern_status / root_cause_status | B3: diagnosed | C3: Diagnosed | D3: A real cause was found and named for this axis. The matching value column (input_pattern if this is input_pattern_status; root_cause if this is root_cause_status) is filled in — go read it. | E3: GC-003 (Equinix): both status columns = diagnosed, so both input_pattern and root_cause are filled in.
A4: input_pattern_status / root_cause_status | B4: not_applicable | C4: Not applicable | D4: This axis was checked, and it genuinely isn't a factor for this case. The matching value column stays blank ON PURPOSE — that blank is not missing data. | E4: GC-002 (Danaher): input_pattern_status = not_applicable — no JD-text trick, the failure is pure reasoning.
A5: input_pattern_status / root_cause_status | B5: not_yet_diagnosed | C5: Not yet diagnosed | D5: Nobody has actually checked this axis for this case. The matching value column is blank because the answer is UNKNOWN — this is different from not_applicable, which means checked-and-confirmed-absent. | E5: GC-001 (Kira): root_cause_status = not_yet_diagnosed — never separately tested whether reasoning-order also contributed.
A6: SECTION 2 — input_pattern_family (umbrella) and input_pattern (specific) values (only meaningful when input_pattern_status = diagnosed). Both are ip_-prefixed so either value is self-identifying if quoted without its column header. (D-155)
A7: input_pattern_family | B7: ip_location_conflict | C7: Location conflict (family) | D7: Umbrella for any case where two sources of location/geo information about the posting disagree with each other (structured field vs. JD text, or JD text vs. itself). Covers ip_location_field_contradicts_jd_text and any future specific pattern of this shape.
A8: input_pattern_family | B8: ip_signal_unclear | C8: Signal unclear (family) | D8: Umbrella for any case where the relevant signal IS present in the JD but is hard to parse for reasons other than a contradiction — bad grammar, unusual placement, ambiguous wording. Covers ip_remote_stated_but_badly_worded and any future specific pattern of this shape.
A9: input_pattern (specific) | B9: ip_location_field_contradicts_jd_text | C9: Location field contradicts JD text | D9: Family: ip_location_conflict. The posting's own structured/derived location field disagrees with what the JD text itself says about eligible location. Belongs here when a location field (e.g. locations_derived) says one place, and the JD prose states a different, specific eligible location.
A10: input_pattern (specific) | B10: ip_remote_stated_but_badly_worded | C10: Remote stated but badly worded | D10: Family: ip_signal_unclear. The JD DOES explicitly state remote eligibility, but the sentence is grammatically broken or oddly phrased in a way that could plausibly make the signal harder to parse than clean prose.
A11: SECTION 3 — root_cause values (only meaningful when root_cause_status = diagnosed)
A12: root_cause | B12: reasoning_after_verdict | C12: Reasoning after verdict | D12: The prompt's JSON schema lists the verdict field(s) before the reasoning field, so the model commits to an answer before generating any explanation — the 'reasoning' is post-hoc justification, not real deliberation. Belongs here only when this specific mechanism was actually traced (per D-149), not just assumed. | E12: GC-002, GC-003: root cause diagnosed in D-149 from the real Danaher/Equinix remote_check misses.

Sheet Summary
A1: Golden Dataset — Summary (auto-computed from the Golden Dataset sheet)
A2: Formulas read Golden Dataset!A2:T500 live — add rows there and this sheet updates on recalculation.
A4: Overall pass rate
B5: prompt baseline_v4_prompt-2026-08-13 | C5: prompt reasoningredesign_TBD_TBD
A6: Pass rate | B6: =IF(COUNTIFS('Golden Dataset'!R2:R500,"<>")=0,0,COUNTIFS('Golden Dataset'!R2:R500,"PASS")/COUNTIFS('Golden Dataset'!R2:R500,"<>")) -> 0 | C6: =IF(COUNTIFS('Golden Dataset'!T2:T500,"<>")=0,0,COUNTIFS('Golden Dataset'!T2:T500,"PASS")/COUNTIFS('Golden Dataset'!T2:T500,"<>")) -> 0
